============================= test session starts =============================
platform win32 -- Python 3.12.4, pytest-8.3.2, pluggy-1.5.0
rootdir: C:\Users\vmascuser\Documents\decoding-llm-capabilities
configfile: pyproject.toml
collected 15 items

tests\test_unit_tests.py F..............                                 [100%]

================================== FAILURES ===================================
_______________________ test_roman_chat_gpt4o_new_test1 _______________________

    def test_roman_chat_gpt4o_new_test1():
>       roman_chat_gpt4o_new.test1()

tests\test_unit_tests.py:6: 
_ _ _ _ _ _ _ _ _ _ _ _ _ _ _ _ _ _ _ _ _ _ _ _ _ _ _ _ _ _ _ _ _ _ _ _ _ _ _ _

    def test1():
>       assert valid_numeral("XIV") == True, "Test case 1 failed"
E       AssertionError: Test case 1 failed

roman_chat_gpt4o_new.py:65: AssertionError
=========================== short test summary info ===========================
FAILED tests\test_unit_tests.py::test_roman_chat_gpt4o_new_test1 - AssertionE...
======================== 1 failed, 14 passed in 0.03s =========================
